Workbook

Sheet Total 
A1: Note: 4th week meetings, talk about accrued expenses | C1: January | D1: February | E1: March | F1: April | G1: May | H1: June | I1: July | J1: August | K1: September | L1: October | M1: November | N1: December | O1: Total | Q1: 24 vs 25 Bud Var
A2: TOTAL | B2: Actual 2024 | C2: =SUMIFS(C18:C204,$B$18:$B$204,"Actual 2024") -> 279328.95 | D2: =SUMIFS(D18:D204,$B$18:$B$204,"Actual 2024") -> 270214.24 | E2: =SUMIFS(E18:E204,$B$18:$B$204,"Actual 2024") -> 361676.73 | F2: =SUMIFS(F18:F204,$B$18:$B$204,"Actual 2024") -> 340089.85 | G2: =SUMIFS(G18:G204,$B$18:$B$204,"Actual 2024") -> 352828.34 | H2: =SUMIFS(H18:H204,$B$18:$B$204,"Actual 2024") -> 279066.85 | I2: =SUMIFS(I18:I204,$B$18:$B$204,"Actual 2024") -> 304345.61 | J2: =SUMIFS(J18:J204,$B$18:$B$204,"Actual 2024") -> 304643.71 | ... N2: =SUMIFS(N18:N204,$B$18:$B$204,"Actual 2024") -> 300395.3 | O2: =SUM(C2:N2) -> 3803746.5
B3: Estimated 2025 | C3: =SUMIFS(C18:C204,$B$18:$B$204,"Estimated") -> 386832.24 | D3: =SUMIFS(D18:D204,$B$18:$B$204,"Estimated") -> 390190.88 | E3: =SUMIFS(E18:E204,$B$18:$B$204,"Estimated") -> 370736.1 | F3: =SUMIFS(F18:F204,$B$18:$B$204,"Estimated") -> 341182.5 | G3: =SUMIFS(G18:G204,$B$18:$B$204,"Estimated") -> 361749.72 | H3: =SUMIFS(H18:H204,$B$18:$B$204,"Estimated") -> 330303.67 | I3: =SUMIFS(I18:I204,$B$18:$B$204,"Estimated") -> 298664.66 | J3: =SUMIFS(J18:J204,$B$18:$B$204,"Estimated") -> 327027.09 | ... N3: =SUMIFS(N18:N204,$B$18:$B$204,"Estimated") -> 321172.34 | O3: =SUM(C3:N3) -> 4131703.6
B4: Budget | C4: =SUMIFS(C18:C204,$B$18:$B$204,"Budget") -> 343948.15 | D4: =SUMIFS(D18:D204,$B$18:$B$204,"Budget") -> 389470.6 | E4: =SUMIFS(E18:E204,$B$18:$B$204,"Budget") -> 369659.21 | F4: =SUMIFS(F18:F204,$B$18:$B$204,"Budget") -> 337869.28 | G4: =SUMIFS(G18:G204,$B$18:$B$204,"Budget") -> 349380.65 | H4: =SUMIFS(H18:H204,$B$18:$B$204,"Budget") -> 323922 | I4: =SUMIFS(I18:I204,$B$18:$B$204,"Budget") -> 299871.66 | J4: =SUMIFS(J18:J204,$B$18:$B$204,"Budget") -> 315111.1 | ... N4: =SUMIFS(N18:N204,$B$18:$B$204,"Budget") -> 319183.58 | O4: =SUM(C4:N4) -> 4033309.9
B5: Actual | C5: =SUMIFS(C18:C204,$B$18:$B$204,"Actual") -> 356907.3 | D5: =SUMIFS(D18:D204,$B$18:$B$204,"Actual") -> 344891.48 | E5: =SUMIFS(E18:E204,$B$18:$B$204,"Actual") -> 403531.82 | F5: =SUMIFS(F18:F204,$B$18:$B$204,"Actual") -> 381063.99 | G5: =SUMIFS(G18:G204,$B$18:$B$204,"Actual") -> 408641.75 | H5: =SUMIFS(H18:H204,$B$18:$B$204,"Actual") -> 384046.39 | I5: =SUMIFS(I18:I204,$B$18:$B$204,"Actual") -> 392927.52 | J5: =SUMIFS(J18:J204,$B$18:$B$204,"Actual") -> 400678.58 | ... N5: =SUMIFS(N18:N204,$B$18:$B$204,"Actual") -> 0 | O5: =SUM(C5:N5) -> 3636337.2 | Q5: =O3-O2 -> 327957.12 | R5: Change Y/Y | S5: =Q5/O2 -> 0.0862195
B6: Budget Deficit/ Savings | C6: =C14 -> -12959.15 | D6: =D4-D5 -> 44579.12 | E6: =E4-E5 -> -33872.61 | F6: =F4-F5 -> -43194.71 | G6: =G4-G5 -> -59261.1 | H6: =H4-H5 -> -60124.39 | I6: =I4-I5 -> -93055.86 | J6: =J4-J5 -> -85567.48 | O6: =SUM(C6:N6) -> -343456.18 | Q6: =Q28 -> 65960.05 | R6: Change in Performance Based
B7: Year to Date Spend | C7: =SUM($C5:C5) -> 356907.3 | D7: =SUM($C5:D5) -> 701798.78 | E7: =SUM($C5:E5) -> 1105330.6 | F7: =SUM($C5:F5) -> 1486394.6 | G7: =SUM($C5:G5) -> 1895036.3 | H7: =SUM($C5:H5) -> 2279082.7 | I7: =SUM($C5:I5) -> 2672010.2 | J7: =SUM($C5:J5) -> 3072688.8 | O7: =O5 -> 3636337.2 | Q7: =Q5-Q6 -> 261997.07 | R7: Change in everything else | S7: =Q7/O2 -> 0.068878689
B8: YTD Excess From Budget | C8: =C4-C7 -> -12959.15 | D8: =SUM($C4:D4)-D7 -> 31619.97 | E8: =SUM($C4:E4)-E7 -> -2252.64 | F8: =SUM($C4:F4)-F7 -> -45447.35 | G8: =SUM($C4:G4)-G7 -> -104708.45 | H8: =SUM($C4:H4)-H7 -> -164832.84 | I8: =SUM($C4:I4)-I7 -> -257888.7 | J8: =SUM($C4:J4)-J7 -> -343456.18 | O8: =SUM(C8:N8) -> -899925.34
A10: Westbound | B10: Actual 2024 | C10: =SUMIFS(C18:C195,$B$18:$B$195,"Actual 2024") -> 276395.89 | D10: =SUMIFS(D18:D195,$B$18:$B$195,"Actual 2024") -> 265891.91 | E10: =SUMIFS(E18:E195,$B$18:$B$195,"Actual 2024") -> 318342.66 | F10: =SUMIFS(F18:F195,$B$18:$B$195,"Actual 2024") -> 332878.99 | G10: =SUMIFS(G18:G195,$B$18:$B$195,"Actual 2024") -> 348416.69 | H10: =SUMIFS(H18:H195,$B$18:$B$195,"Actual 2024") -> 274374.54 | I10: =SUMIFS(I18:I195,$B$18:$B$195,"Actual 2024") -> 299083.16 | J10: =SUMIFS(J18:J195,$B$18:$B$195,"Actual 2024") -> 299928.02 | ... N10: =SUMIFS(N18:N195,$B$18:$B$195,"Actual 2024") -> 295673.58 | O10: =SUM(C10:N10) -> 3703393
B11: Estimated | C11: =SUMIFS(C18:C195,$B$18:$B$195,"Estimated") -> 386832.24 | D11: =SUMIFS(D18:D195,$B$18:$B$195,"Estimated") -> 390190.88 | E11: =SUMIFS(E18:E195,$B$18:$B$195,"Estimated") -> 370736.1 | F11: =SUMIFS(F18:F195,$B$18:$B$195,"Estimated") -> 341182.5 | G11: =SUMIFS(G18:G195,$B$18:$B$195,"Estimated") -> 361749.72 | H11: =SUMIFS(H18:H195,$B$18:$B$195,"Estimated") -> 330303.67 | I11: =SUMIFS(I18:I195,$B$18:$B$195,"Estimated") -> 298664.66 | J11: =SUMIFS(J18:J195,$B$18:$B$195,"Estimated") -> 327027.09 | ... N11: =SUMIFS(N18:N195,$B$18:$B$195,"Estimated") -> 321172.34 | O11: =SUM(C11:N11) -> 4131703.6
B12: Budget | C12: =SUMIFS(C18:C195,$B$18:$B$195,"Budget") -> 343948.15 | D12: =SUMIFS(D18:D195,$B$18:$B$195,"Budget") -> 389470.6 | E12: =SUMIFS(E18:E195,$B$18:$B$195,"Budget") -> 369659.21 | F12: =SUMIFS(F18:F195,$B$18:$B$195,"Budget") -> 337869.28 | G12: =SUMIFS(G18:G195,$B$18:$B$195,"Budget") -> 349380.65 | H12: =SUMIFS(H18:H195,$B$18:$B$195,"Budget") -> 323922 | I12: =SUMIFS(I18:I195,$B$18:$B$195,"Budget") -> 299871.66 | J12: =SUMIFS(J18:J195,$B$18:$B$195,"Budget") -> 315111.1 | ... N12: =SUMIFS(N18:N195,$B$18:$B$195,"Budget") -> 319183.58 | O12: =SUM(C12:N12) -> 4033309.9
B13: Actual | C13: =SUMIFS(C18:C195,$B$18:$B$195,"Actual") -> 356907.3 | D13: =SUMIFS(D18:D195,$B$18:$B$195,"Actual") -> 344891.48 | E13: =SUMIFS(E18:E195,$B$18:$B$195,"Actual") -> 403531.82 | F13: =SUMIFS(F18:F195,$B$18:$B$195,"Actual") -> 381063.99 | G13: =SUMIFS(G18:G195,$B$18:$B$195,"Actual") -> 408641.75 | H13: =SUMIFS(H18:H195,$B$18:$B$195,"Actual") -> 384046.39 | I13: =SUMIFS(I18:I195,$B$18:$B$195,"Actual") -> 392927.52 | J13: =SUMIFS(J18:J195,$B$18:$B$195,"Actual") -> 400678.58 | ... N13: =SUMIFS(N18:N195,$B$18:$B$195,"Actual") -> 0 | O13: =SUM(C13:N13) -> 3636337.2
B14: Budget Deficit/ Savings | C14: =C12-C13 -> -12959.15 | D14: =D12-D13 -> 44579.12 | E14: =E12-E13 -> -33872.61 | F14: =F12-F13 -> -43194.71 | G14: =G12-G13 -> -59261.1 | H14: =H12-H13 -> -60124.39 | I14: =I12-I13 -> -93055.86 | J14: =J12-J13 -> -85567.48 | ... L14: =L12-L13 -> 71059.4 | O14: =SUM(C14:N14) -> -221504.76
B15: Year to Date Spend | C15: =SUM($C13:C13) -> 356907.3 | D15: =SUM($C13:D13) -> 701798.78 | E15: =SUM($C13:E13) -> 1105330.6 | F15: =SUM($C13:F13) -> 1486394.6 | G15: =SUM($C13:G13) -> 1895036.3 | H15: =SUM($C13:H13) -> 2279082.7 | I15: =SUM($C13:I13) -> 2672010.2 | J15: =SUM($C13:J13) -> 3072688.8 | ... L15: =SUM($C13:L13) -> 3629360.4 | O15: =O13 -> 3636337.2
B16: YTD Excess From Budget | C16: =SUM($C12:C12)-C15 -> -12959.15 | D16: =SUM($C12:D12)-D15 -> 31619.97 | E16: =SUM($C12:E12)-E15 -> -2252.64 | F16: =SUM($C12:F12)-F15 -> -45447.35 | G16: =SUM($C12:G12)-G15 -> -104708.45 | H16: =SUM($C12:H12)-H15 -> -164832.84 | I16: =SUM($C12:I12)-I15 -> -257888.7 | J16: =SUM($C12:J12)-J15 -> -343456.18 | ... L16: =SUM($C12:L12)-L15 -> -221504.76 | O16: =SUM(C16:N16) -> -1413994.3
A18: Individual Contractors 5024-510 | B18: Actual 2024 | C18: ='5024-510 Individual Contractors'!C3 -> 15182.75 | D18: ='5024-510 Individual Contractors'!D3 -> 14877.45 | E18: ='5024-510 Individual Contractors'!E3 -> 15152.75 | F18: ='5024-510 Individual Contractors'!F3 -> 15467 | G18: ='5024-510 Individual Contractors'!G3 -> 16872.5 | H18: ='5024-510 Individual Contractors'!H3 -> 15506.5 | I18: ='5024-510 Individual Contractors'!I3 -> 22385.5 | J18: ='5024-510 Individual Contractors'!J3 -> 23444 | ... O18: ='5024-510 Individual Contractors'!O3 -> 235250.45
B19: Estimated | C19: ='5024-510 Individual Contractors'!C4 -> 25473 | D19: ='5024-510 Individual Contractors'!D4 -> 25473 | E19: ='5024-510 Individual Contractors'!E4 -> 25473 | F19: ='5024-510 Individual Contractors'!F4 -> 25473 | G19: ='5024-510 Individual Contractors'!G4 -> 25473 | H19: ='5024-510 Individual Contractors'!H4 -> 25473 | I19: ='5024-510 Individual Contractors'!I4 -> 25473 | J19: ='5024-510 Individual Contractors'!J4 -> 25473 | ... O19: ='5024-510 Individual Contractors'!O4 -> 305676 | Q19: =O19-O18 -> 70425.55 | R19: $21K moved from General Contracted (5310-510) to this acct.
B20: Budget | C20: ='5024-510 Individual Contractors'!C5 -> 23573 | D20: ='5024-510 Individual Contractors'!D5 -> 23573 | E20: ='5024-510 Individual Contractors'!E5 -> 23573 | F20: ='5024-510 Individual Contractors'!F5 -> 23573 | G20: ='5024-510 Individual Contractors'!G5 -> 23573 | H20: ='5024-510 Individual Contractors'!H5 -> 23573 | I20: ='5024-510 Individual Contractors'!I5 -> 23573 | J20: ='5024-510 Individual Contractors'!J5 -> 23573 | ... O20: ='5024-510 Individual Contractors'!O5 -> 282876
B21: Actual | C21: ='5024-510 Individual Contractors'!C6 -> 25960.83 | D21: ='5024-510 Individual Contractors'!D6 -> 23257.83 | E21: ='5024-510 Individual Contractors'!E6 -> 26377 | F21: ='5024-510 Individual Contractors'!F6 -> 36213.01 | G21: ='5024-510 Individual Contractors'!G6 -> 66882.95 | H21: ='5024-510 Individual Contractors'!H6 -> 49229.95 | I21: ='5024-510 Individual Contractors'!I6 -> 37253.5 | J21: ='5024-510 Individual Contractors'!J6 -> 19065 | ... O21: ='5024-510 Individual Contractors'!O6 -> 315566.74 | Q21: =Q19+Q96 -> 49252.2 | R21: Actual Change
A22: Any work done by individual Contractors, regardless of the activity done. | B22: Budget Deficit/ Savings | C22: ='5024-510 Individual Contractors'!C7 -> -2387.83 | D22: ='5024-510 Individual Contractors'!D7 -> 315.17 | E22: ='5024-510 Individual Contractors'!E7 -> -2804 | F22: ='5024-510 Individual Contractors'!F7 -> -12640.01 | G22: ='5024-510 Individual Contractors'!G7 -> -43309.95 | H22: ='5024-510 Individual Contractors'!H7 -> -25656.95 | I22: ='5024-510 Individual Contractors'!I7 -> -13680.5 | J22: ='5024-510 Individual Contractors'!J7 -> 4508 | ... O22: ='5024-510 Individual Contractors'!O7 -> -32690.74 | R22: Primarily--web design, Japan & Korea support and Optimizely Testing
B23: Year to Date Spend | C23: ='5024-510 Individual Contractors'!C8 -> 25960.83 | D23: ='5024-510 Individual Contractors'!D8 -> 49218.66 | E23: ='5024-510 Individual Contractors'!E8 -> 75595.66 | F23: ='5024-510 Individual Contractors'!F8 -> 111808.67 | G23: ='5024-510 Individual Contractors'!G8 -> 178691.62 | H23: ='5024-510 Individual Contractors'!H8 -> 227921.57 | I23: ='5024-510 Individual Contractors'!I8 -> 265175.07 | J23: ='5024-510 Individual Contractors'!J8 -> 284240.07 | ... O23: ='5024-510 Individual Contractors'!O8 -> 315566.74
B24: YTD Excess From Budget | C24: ='5024-510 Individual Contractors'!C9 -> -2387.83 | D24: ='5024-510 Individual Contractors'!D9 -> -2072.66 | E24: ='5024-510 Individual Contractors'!E9 -> -4876.66 | F24: ='5024-510 Individual Contractors'!F9 -> -17516.67 | G24: ='5024-510 Individual Contractors'!G9 -> -60826.62 | H24: ='5024-510 Individual Contractors'!H9 -> -86483.57 | I24: ='5024-510 Individual Contractors'!I9 -> -100164.07 | J24: ='5024-510 Individual Contractors'!J9 -> -95656.07 | ... O24: ='5024-510 Individual Contractors'!O9 -> 0
A27: Performance based 5100-510 | B27: Actual 2024 | C27: ='5100-510 Performance based'!C3 -> 143539.3 | D27: ='5100-510 Performance based'!D3 -> 147248.13 | E27: ='5100-510 Performance based'!E3 -> 185140.97 | F27: ='5100-510 Performance based'!F3 -> 169233.26 | G27: ='5100-510 Performance based'!G3 -> 176262.06 | H27: ='5100-510 Performance based'!H3 -> 149970.94 | I27: ='5100-510 Performance based'!I3 -> 177140.26 | J27: ='5100-510 Performance based'!J3 -> 155860.75 | ... O27: ='5100-510 Performance based'!O3 -> 1976450.7
B28: Estimated | C28: ='5100-510 Performance based'!C4 -> 146953 | D28: ='5100-510 Performance based'!D4 -> 180607.9 | E28: ='5100-510 Performance based'!E4 -> 187009.76 | F28: ='5100-510 Performance based'!F4 -> 174751.99 | G28: ='5100-510 Performance based'!G4 -> 176957.38 | H28: ='5100-510 Performance based'!H4 -> 173636.33 | I28: ='5100-510 Performance based'!I4 -> 175447.32 | J28: ='5100-510 Performance based'!J4 -> 166596.13 | ... O28: ='5100-510 Performance based'!O4 -> 2042410.7 | Q28: =O28-O27 -> 65960.05
B29: Budget | C29: ='5100-510 Performance based'!C5 -> 154148.08 | D29: ='5100-510 Performance based'!D5 -> 189450.78 | E29: ='5100-510 Performance based'!E5 -> 196166.08 | F29: ='5100-510 Performance based'!F5 -> 183308.15 | G29: ='5100-510 Performance based'!G5 -> 185621.52 | H29: ='5100-510 Performance based'!H5 -> 182137.87 | I29: ='5100-510 Performance based'!I5 -> 184037.53 | J29: ='5100-510 Performance based'!J5 -> 174752.97 | ... O29: ='5100-510 Performance based'!O5 -> 2142410.7
B30: Actual | C30: ='5100-510 Performance based'!C6 -> 167533.56 | D30: ='5100-510 Performance based'!D6 -> 177155.24 | E30: ='5100-510 Performance based'!E6 -> 194641.2 | F30: ='5100-510 Performance based'!F6 -> 189109.5 | G30: ='5100-510 Performance based'!G6 -> 186083.66 | H30: ='5100-510 Performance based'!H6 -> 186467.29 | I30: ='5100-510 Performance based'!I6 -> 218352.1 | J30: ='5100-510 Performance based'!J6 -> 206940.24 | ... O30: ='5100-510 Performance based'!O6 -> 1828114.5
A31: Ad Expenses that can be tracked by their association to Rev | B31: Budget Deficit/ Savings | C31: ='5100-510 Performance based'!C7 -> -13385.48 | D31: ='5100-510 Performance based'!D7 -> 12295.54 | E31: ='5100-510 Performance based'!E7 -> 1524.88 | F31: ='5100-510 Performance based'!F7 -> -5801.35 | G31: ='5100-510 Performance based'!G7 -> -462.14 | H31: ='5100-510 Performance based'!H7 -> -4329.42 | I31: ='5100-510 Performance based'!I7 -> -34314.57 | J31: ='5100-510 Performance based'!J7 -> -32187.27 | ... O31: ='5100-510 Performance based'!O7 -> 314296.21
B32: Year to Date Spend | C32: ='5100-510 Performance based'!C8 -> 167533.56 | D32: ='5100-510 Performance based'!D8 -> 344688.8 | E32: ='5100-510 Performance based'!E8 -> 539330 | F32: ='5100-510 Performance based'!F8 -> 728439.5 | G32: ='5100-510 Performance based'!G8 -> 914523.16 | H32: ='5100-510 Performance based'!H8 -> 1100990.4 | I32: ='5100-510 Performance based'!I8 -> 1319342.6 | J32: ='5100-510 Performance based'!J8 -> 1526282.8 | ... O32: ='5100-510 Performance based'!O8 -> 1828114.5
B33: YTD Excess From Budget | C33: ='5100-510 Performance based'!C9 -> -13385.48 | D33: ='5100-510 Performance based'!D9 -> -1089.94 | E33: ='5100-510 Performance based'!E9 -> 434.94 | F33: ='5100-510 Performance based'!F9 -> -5366.41 | G33: ='5100-510 Performance based'!G9 -> -5828.55 | H33: ='5100-510 Performance based'!H9 -> -10157.97 | I33: ='5100-510 Performance based'!I9 -> -44472.54 | J33: ='5100-510 Performance based'!J9 -> -76659.81 | ... O33: ='5100-510 Performance based'!O9 -> 0
A36: Non performance based 5101-510 | B36: Actual 2024 | C36: ='5101-510 Non performance based'!C3 -> 54961.34 | D36: ='5101-510 Non performance based'!D3 -> 52303.61 | E36: ='5101-510 Non performance based'!E3 -> 53970.61 | F36: ='5101-510 Non performance based'!F3 -> 62526.2 | G36: ='5101-510 Non performance based'!G3 -> 50448.93 | H36: ='5101-510 Non performance based'!H3 -> 33734.71 | I36: ='5101-510 Non performance based'!I3 -> 36157.39 | J36: ='5101-510 Non performance based'!J3 -> 43318.85 | ... O36: ='5101-510 Non performance based'!O3 -> 579457.29
B37: Estimated | C37: ='5101-510 Non performance based'!C4 -> 73939 | D37: ='5101-510 Non performance based'!D4 -> 58654 | E37: ='5101-510 Non performance based'!E4 -> 50860 | F37: ='5101-510 Non performance based'!F4 -> 64316 | G37: ='5101-510 Non performance based'!G4 -> 47360 | H37: ='5101-510 Non performance based'!H4 -> 42133 | I37: ='5101-510 Non performance based'!I4 -> 29860 | J37: ='5101-510 Non performance based'!J4 -> 43399 | ... O37: ='5101-510 Non performance based'!O4 -> 605565 | Q37: =O37-O36 -> 26107.71 | R37: Adding Japan Marketing
B38: Budget | C38: ='5101-510 Non performance based'!C5 -> 75939 | D38: ='5101-510 Non performance based'!D5 -> 58654 | E38: ='5101-510 Non performance based'!E5 -> 50860 | F38: ='5101-510 Non performance based'!F5 -> 66316 | G38: ='5101-510 Non performance based'!G5 -> 47360 | H38: ='5101-510 Non performance based'!H5 -> 42133 | I38: ='5101-510 Non performance based'!I5 -> 31860 | J38: ='5101-510 Non performance based'!J5 -> 43399 | ... O38: ='5101-510 Non performance based'!O5 -> 613565
B39: Actual | C39: ='5101-510 Non performance based'!C6 -> 48578.52 | D39: ='5101-510 Non performance based'!D6 -> 47324.93 | E39: ='5101-510 Non performance based'!E6 -> 43482.71 | F39: ='5101-510 Non performance based'!F6 -> 73020.92 | G39: ='5101-510 Non performance based'!G6 -> 35157.55 | H39: ='5101-510 Non performance based'!H6 -> 57157.04 | I39: ='5101-510 Non performance based'!I6 -> 37818.82 | J39: ='5101-510 Non performance based'!J6 -> 50222.33 | ... O39: ='5101-510 Non performance based'!O6 -> 491972.19
A40: Other Ad Expenses | B40: Budget Deficit/ Savings | C40: ='5101-510 Non performance based'!C7 -> 27360.48 | D40: ='5101-510 Non performance based'!D7 -> 11329.07 | E40: ='5101-510 Non performance based'!E7 -> 7377.29 | F40: ='5101-510 Non performance based'!F7 -> -6704.92 | G40: ='5101-510 Non performance based'!G7 -> 12202.45 | H40: ='5101-510 Non performance based'!H7 -> -15024.04 | I40: ='5101-510 Non performance based'!I7 -> -5958.82 | J40: ='5101-510 Non performance based'!J7 -> -6823.33 | ... O40: ='5101-510 Non performance based'!O7 -> 121592.81
B41: Year to Date Spend | C41: ='5101-510 Non performance based'!C8 -> 48578.52 | D41: ='5101-510 Non performance based'!D8 -> 95903.45 | E41: ='5101-510 Non performance based'!E8 -> 139386.16 | F41: ='5101-510 Non performance based'!F8 -> 212407.08 | G41: ='5101-510 Non performance based'!G8 -> 247564.63 | H41: ='5101-510 Non performance based'!H8 -> 304721.67 | I41: ='5101-510 Non performance based'!I8 -> 342540.49 | J41: ='5101-510 Non performance based'!J8 -> 392762.82 | ... O41: ='5101-510 Non performance based'!O8 -> 491972.19
B42: YTD Excess From Budget | C42: ='5101-510 Non performance based'!C9 -> 27360.48 | D42: ='5101-510 Non performance based'!D9 -> 38689.55 | E42: ='5101-510 Non performance based'!E9 -> 46066.84 | F42: ='5101-510 Non performance based'!F9 -> 39361.92 | G42: ='5101-510 Non performance based'!G9 -> 51564.37 | H42: ='5101-510 Non performance based'!H9 -> 36540.33 | I42: ='5101-510 Non performance based'!I9 -> 30581.51 | J42: ='5101-510 Non performance based'!J9 -> 23758.18 | ... O42: ='5101-510 Non performance based'!O9 -> 0
A45: Advertising Agency Fee 5102-510 | B45: Actual 2024 | C45: ='5102-510 Advertising Agency Fee'!C3 -> 30663.22 | D45: ='5102-510 Advertising Agency Fee'!D3 -> 34061.61 | E45: ='5102-510 Advertising Agency Fee'!E3 -> 48123.82 | F45: ='5102-510 Advertising Agency Fee'!F3 -> 35442.91 | G45: ='5102-510 Advertising Agency Fee'!G3 -> 57806.73 | H45: ='5102-510 Advertising Agency Fee'!H3 -> 42091.03 | I45: ='5102-510 Advertising Agency Fee'!I3 -> 39212.95 | J45: ='5102-510 Advertising Agency Fee'!J3 -> 38385.77 | ... O45: ='5102-510 Advertising Agency Fee'!O3 -> 489117.25
B46: Estimated | C46: ='5102-510 Advertising Agency Fee'!C4 -> 67567 | D46: ='5102-510 Advertising Agency Fee'!D4 -> 97522 | E46: ='5102-510 Advertising Agency Fee'!E4 -> 58826 | F46: ='5102-510 Advertising Agency Fee'!F4 -> 51522 | G46: ='5102-510 Advertising Agency Fee'!G4 -> 65022 | H46: ='5102-510 Advertising Agency Fee'!H4 -> 49022 | I46: ='5102-510 Advertising Agency Fee'!I4 -> 47085 | J46: ='5102-510 Advertising Agency Fee'!J4 -> 47022 | ... O46: ='5102-510 Advertising Agency Fee'!O4 -> 697176 | Q46: =O46-O45 -> 208058.75 | R46: Annual Fee increases (mostly World Media)
B47: Budget | C47: ='5102-510 Advertising Agency Fee'!C5 -> 67567 | D47: ='5102-510 Advertising Agency Fee'!D5 -> 97522 | E47: ='5102-510 Advertising Agency Fee'!E5 -> 58826 | F47: ='5102-510 Advertising Agency Fee'!F5 -> 51522 | G47: ='5102-510 Advertising Agency Fee'!G5 -> 65022 | H47: ='5102-510 Advertising Agency Fee'!H5 -> 49022 | I47: ='5102-510 Advertising Agency Fee'!I5 -> 47085 | J47: ='5102-510 Advertising Agency Fee'!J5 -> 47022 | ... O47: ='5102-510 Advertising Agency Fee'!O5 -> 697176
B48: Actual | C48: ='5102-510 Advertising Agency Fee'!C6 -> 51418.5 | D48: ='5102-510 Advertising Agency Fee'!D6 -> 59616.7 | E48: ='5102-510 Advertising Agency Fee'!E6 -> 47803.15 | F48: ='5102-510 Advertising Agency Fee'!F6 -> 54958.58 | G48: ='5102-510 Advertising Agency Fee'!G6 -> 55320.83 | H48: ='5102-510 Advertising Agency Fee'!H6 -> 58388.51 | I48: ='5102-510 Advertising Agency Fee'!I6 -> 63125.88 | J48: ='5102-510 Advertising Agency Fee'!J6 -> 59393.07 | ... O48: ='5102-510 Advertising Agency Fee'!O6 -> 528819.66
...

Sheet Adjustment

Sheet 5024-510 Individual Contractors
A1: 5024-510 Individual Contractors
C2: January | D2: February | E2: March | F2: April | G2: May | H2: June | I2: July | J2: August | K2: September | L2: October | M2: November | N2: December | O2: Total
A3: TOTAL | B3: Actual 2024 | C3: =SUMIFS(C$11:C971,$B$11:$B971,"Actual 2024") -> 15182.75 | D3: =SUMIFS(D$11:D971,$B$11:$B971,"Actual 2024") -> 14877.45 | E3: =SUMIFS(E$11:E971,$B$11:$B971,"Actual 2024") -> 15152.75 | F3: =SUMIFS(F$11:F971,$B$11:$B971,"Actual 2024") -> 15467 | G3: =SUMIFS(G$11:G971,$B$11:$B971,"Actual 2024") -> 16872.5 | H3: =SUMIFS(H$11:H971,$B$11:$B971,"Actual 2024") -> 15506.5 | I3: =SUMIFS(I$11:I971,$B$11:$B971,"Actual 2024") -> 22385.5 | J3: =SUMIFS(J$11:J971,$B$11:$B971,"Actual 2024") -> 23444 | ... O3: =SUMIFS(O$11:O971,$B$11:$B971,"Actual 2024") -> 235250.45
B4: Estimated | C4: =SUMIFS(C$11:C971,$B$11:$B971,"Estimated") -> 25473 | D4: =SUMIFS(D$11:D971,$B$11:$B971,"Estimated") -> 25473 | E4: =SUMIFS(E$11:E971,$B$11:$B971,"Estimated") -> 25473 | F4: =SUMIFS(F$11:F971,$B$11:$B971,"Estimated") -> 25473 | G4: =SUMIFS(G$11:G971,$B$11:$B971,"Estimated") -> 25473 | H4: =SUMIFS(H$11:H971,$B$11:$B971,"Estimated") -> 25473 | I4: =SUMIFS(I$11:I971,$B$11:$B971,"Estimated") -> 25473 | J4: =SUMIFS(J$11:J971,$B$11:$B971,"Estimated") -> 25473 | ... O4: =SUMIFS(O$11:O971,$B$11:$B971,"Estimated") -> 305676
B5: Budget | C5: 23573 | D5: 23573 | E5: 23573 | F5: 23573 | G5: 23573 | H5: 23573 | I5: 23573 | J5: 23573 | K5: 23573 | L5: 23573 | M5: 23573 | N5: 23573 | O5: =SUM(C5:N5) -> 282876 | P5: 282876
B6: Actual | C6: =SUMIFS(C$11:C976,$B$11:$B976,"Actual") -> 25960.83 | D6: =SUMIFS(D$11:D976,$B$11:$B976,"Actual") -> 23257.83 | E6: =SUMIFS(E$11:E976,$B$11:$B976,"Actual") -> 26377 | F6: =SUMIFS(F$11:F976,$B$11:$B976,"Actual") -> 36213.01 | G6: =SUMIFS(G$11:G976,$B$11:$B976,"Actual") -> 66882.95 | H6: =SUMIFS(H$11:H976,$B$11:$B976,"Actual") -> 49229.95 | I6: =SUMIFS(I$11:I976,$B$11:$B976,"Actual") -> 37253.5 | J6: =SUMIFS(J$11:J976,$B$11:$B976,"Actual") -> 19065 | ... O6: =SUMIFS(O$11:O976,$B$11:$B976,"Actual") -> 315566.74
B7: Budget Deficit/ Savings | C7: =C5-C6 -> -2387.83 | D7: =D5-D6 -> 315.17 | E7: =E5-E6 -> -2804 | F7: =F5-F6 -> -12640.01 | G7: =G5-G6 -> -43309.95 | H7: =H5-H6 -> -25656.95 | I7: =I5-I6 -> -13680.5 | J7: =J5-J6 -> 4508 | ... O7: =O5-O6 -> -32690.74
B8: Year to Date Spend | C8: =SUM($C6:C6) -> 25960.83 | D8: =SUM($C6:D6) -> 49218.66 | E8: =SUM($C6:E6) -> 75595.66 | F8: =SUM($C6:F6) -> 111808.67 | G8: =SUM($C6:G6) -> 178691.62 | H8: =SUM($C6:H6) -> 227921.57 | I8: =SUM($C6:I6) -> 265175.07 | J8: =SUM($C6:J6) -> 284240.07 | ... N8: =SUM($C6:N6) -> 318959.57 | O8: =O6 -> 315566.74
B9: YTD Excess From Budget | C9: =SUM($C5:C5)-C8 -> -2387.83 | D9: =SUM($C5:D5)-D8 -> -2072.66 | E9: =SUM($C5:E5)-E8 -> -4876.66 | F9: =SUM($C5:F5)-F8 -> -17516.67 | G9: =SUM($C5:G5)-G8 -> -60826.62 | H9: =SUM($C5:H5)-H8 -> -86483.57 | I9: =SUM($C5:I5)-I8 -> -100164.07 | J9: =SUM($C5:J5)-J8 -> -95656.07 | ... N9: =SUM($C5:N5)-N8 -> -36083.57 | T9: d
A11: Harley Charlebois | B11: Actual 2024 | C11: 4836 | D11: 4316 | E11: 4160 | F11: 4992 | G11: 6136 | H11: 5928 | I11: 6136 | J11: 6526 | K11: 4160 | L11: 4160 | M11: 4160 | N11: 5290 | O11: =SUM(C11:N11) -> 60800
B12: Estimated | C12: 3700 | D12: 3700 | E12: 3700 | F12: 3700 | G12: 3700 | H12: 3700 | I12: 3700 | J12: 3700 | K12: 3700 | L12: 3700 | M12: 3700 | N12: 3700 | O12: =SUM(C12:N12) -> 44400 | Q12: She is doing copywriting
B13: Budget | O13: =SUM(C13:N13) -> 0
B14: Actual | C14: 4160 | D14: 4160 | E14: 4160 | F14: =3120+2080 -> 5200 | G14: 3120 | H14: =2080+1080+2080 -> 5240 | I14: =2080 -> 2080 | J14: =2080+2080 -> 4160 | K14: 2080 | L14: 2080 | O14: =SUM(C14:N14) -> 36440
A15: Ephraim Tacuban | B15: Actual 2024 | C15: 3291.75 | D15: 3506.45 | E15: 3557.75 | F15: 3420 | G15: 3325 | H15: 3496 | I15: 3572 | J15: 3591 | K15: 3705 | L15: 4101 | M15: 3990 | N15: 3705 | O15: =SUM(C15:N15) -> 43260.95
B16: Estimated | C16: 3040 | D16: 3040 | E16: 3040 | F16: 3040 | G16: 3040 | H16: 3040 | I16: 3040 | J16: 3040 | K16: 3040 | L16: 3040 | M16: 3040 | N16: 3040 | O16: =SUM(C16:N16) -> 36480 | Q16: Web design
B17: Budget | O17: =SUM(C17:N17) -> 0
B18: Actual | C18: 3990 | D18: 3648 | E18: 3344 | F18: 1748 | G18: 3496 | H18: 3496 | I18: =3496 -> 3496 | J18: =3496 -> 3496 | O18: =SUM(C18:N18) -> 26714
A19: Shazer Llanera | B19: Actual 2024 | C19: 2400 | D19: 2400 | E19: 2400 | F19: 2400 | G19: 2400 | H19: 2400 | I19: 2400 | J19: 2400 | K19: 2400 | L19: 2400 | M19: 2400 | N19: 2400 | O19: =SUM(C19:N19) -> 28800
B20: Estimated | C20: 2400 | D20: 2400 | E20: 2400 | F20: 2400 | G20: 2400 | H20: 2400 | I20: 2400 | J20: 2400 | K20: 2400 | L20: 2400 | M20: 2400 | N20: 2400 | O20: =SUM(C20:N20) -> 28800 | Q20: Web design
B21: Budget | O21: =SUM(C21:N21) -> 0
B22: Actual | C22: 2400 | D22: 2400 | E22: 2400 | F22: 2400 | G22: 2400 | H22: 2400 | I22: 2400 | J22: 2400 | O22: =SUM(C22:N22) -> 19200
A23: Nani Laie (Mike Foley) | B23: Actual 2024 | C23: 3135 | D23: 3135 | E23: 3135 | F23: 3135 | G23: 3135 | H23: 1562.5 | I23: 1562.5 | J23: 3125 | K23: 3125 | L23: 3125 | M23: 3125 | N23: 2090 | O23: =SUM(C23:N23) -> 33390
B24: Estimated | C24: 2613 | D24: 2613 | E24: 2613 | F24: 2613 | G24: 2613 | H24: 2613 | I24: 2613 | J24: 2613 | K24: 2613 | L24: 2613 | M24: 2613 | N24: 2613 | O24: =SUM(C24:N24) -> 31356 | Q24: Copywrighting and Legacy
B25: Budget | O25: =SUM(C25:N25) -> 0
B26: Actual | C26: 2252.83 | D26: 2252.83 | E26: 3135 | F26: 3125.5 | G26: 3135.5 | H26: 3135.5 | I26: 3135.5 | K26: 3135.5 | O26: =SUM(D26:N26) -> 21055.33 | T26: =5*40*52 -> 10400
A27: Sam Merrill | B27: Actual 2024 | O27: =SUM(C27:N27) -> 0 | T27: =2*5*40*52 -> 20800
B28: Estimated | C28: 0 | D28: 0 | E28: 0 | F28: 0 | G28: 0 | H28: 0 | I28: 0 | J28: 0 | K28: 0 | L28: 0 | M28: 0 | N28: 0 | O28: =SUM(C28:N28) -> 0 | T28: =SUM(T26:T29) -> 49400
B29: Budget | O29: =SUM(C29:N29) -> 0 | T29: =2*5*35*52 -> 18200
B30: Actual | G30: 2420 | O30: =SUM(C30:N30) -> 2420
A31: Conor Lunt | B31: Actual 2024 | O31: =SUM(C31:N31) -> 0
B32: Estimated | C32: 0 | D32: 0 | E32: 0 | F32: 0 | G32: 0 | H32: 0 | I32: 0 | J32: 0 | K32: 0 | L32: 0 | M32: 0 | N32: 0 | O32: =SUM(C32:N32) -> 0
B33: Budget | O33: =SUM(C33:N33) -> 0
B34: Actual | G34: 4102.5 | O34: =SUM(C34:N34) -> 4102.5
A35: Tanner Fernandez | B35: Actual 2024 | O35: =SUM(C35:N35) -> 0
B36: Estimated | C36: 1000 | D36: 1000 | E36: 1000 | F36: 1000 | G36: 1000 | H36: 1000 | I36: 1000 | J36: 1000 | K36: 1000 | L36: 1000 | M36: 1000 | N36: 1000 | O36: =SUM(C36:N36) -> 12000
B37: Budget | O37: =SUM(C37:N37) -> 0
B38: Actual | O38: =SUM(C38:N38) -> 0
A39: Marc Purles | B39: Actual 2024 | C39: 1520 | D39: 1520 | E39: 1900 | F39: 1520 | G39: 1520 | H39: 1520 | I39: 1520 | J39: 1520 | K39: 1520 | L39: 1520 | M39: 1520 | N39: 1520 | O39: =SUM(C39:N39) -> 18620
B40: Estimated | C40: 1500 | D40: 1500 | E40: 1500 | F40: 1500 | G40: 1500 | H40: 1500 | I40: 1500 | J40: 1500 | K40: 1500 | L40: 1500 | M40: 1500 | N40: 1500 | O40: =SUM(C40:N40) -> 18000 | Q40: Online product sales--ex-Sr missionary
B41: Budget | O41: =SUM(C41:N41) -> 0
...

Sheet 5100-510 Performance based
A1: 5100-510 Performance based
C2: January | D2: February | E2: March | F2: April | G2: May | H2: June | I2: July | J2: August | K2: September | L2: October | M2: November | N2: December | O2: Total
A3: TOTAL | B3: Actual 2024 | C3: =SUMIFS(C$11:C944,$B$11:$B944,"Actual 2024") -> 143539.3 | D3: =SUMIFS(D$11:D944,$B$11:$B944,"Actual 2024") -> 147248.13 | E3: =SUMIFS(E$11:E944,$B$11:$B944,"Actual 2024") -> 185140.97 | F3: =SUMIFS(F$11:F944,$B$11:$B944,"Actual 2024") -> 169233.26 | G3: =SUMIFS(G$11:G944,$B$11:$B944,"Actual 2024") -> 176262.06 | H3: =SUMIFS(H$11:H944,$B$11:$B944,"Actual 2024") -> 149970.94 | I3: =SUMIFS(I$11:I944,$B$11:$B944,"Actual 2024") -> 177140.26 | J3: =SUMIFS(J$11:J944,$B$11:$B944,"Actual 2024") -> 155860.75 | ... O3: =SUMIFS(O$11:O944,$B$11:$B944,"Actual 2024") -> 1976450.7
B4: Estimated | C4: =SUMIFS(C$11:C944,$B$11:$B944,"Estimated") -> 146953 | D4: =SUMIFS(D$11:D944,$B$11:$B944,"Estimated") -> 180607.9 | E4: =SUMIFS(E$11:E944,$B$11:$B944,"Estimated") -> 187009.76 | F4: =SUMIFS(F$11:F944,$B$11:$B944,"Estimated") -> 174751.99 | G4: =SUMIFS(G$11:G944,$B$11:$B944,"Estimated") -> 176957.38 | H4: =SUMIFS(H$11:H944,$B$11:$B944,"Estimated") -> 173636.33 | I4: =SUMIFS(I$11:I944,$B$11:$B944,"Estimated") -> 175447.32 | J4: =SUMIFS(J$11:J944,$B$11:$B944,"Estimated") -> 166596.13 | ... O4: =SUMIFS(O$11:O944,$B$11:$B944,"Estimated") -> 2042410.7 | Q4: =O4-O3 -> 65960.05
B5: Budget | C5: 154148.08 | D5: 189450.78 | E5: 196166.08 | F5: 183308.15 | G5: 185621.52 | H5: 182137.87 | I5: 184037.53 | J5: 174752.97 | K5: 179128.29 | L5: 171152.46 | M5: 170804.54 | N5: 171702.45 | O5: =SUM(C5:N5) -> 2142410.7 | P5: 2142410.7
B6: Actual | C6: =SUMIFS(C$11:C973,$B$11:$B973,"Actual") -> 167533.56 | D6: =SUMIFS(D$11:D973,$B$11:$B973,"Actual") -> 177155.24 | E6: =SUMIFS(E$11:E973,$B$11:$B973,"Actual") -> 194641.2 | F6: =SUMIFS(F$11:F973,$B$11:$B973,"Actual") -> 189109.5 | G6: =SUMIFS(G$11:G973,$B$11:$B973,"Actual") -> 186083.66 | H6: =SUMIFS(H$11:H973,$B$11:$B973,"Actual") -> 186467.29 | I6: =SUMIFS(I$11:I973,$B$11:$B973,"Actual") -> 218352.1 | J6: =SUMIFS(J$11:J973,$B$11:$B973,"Actual") -> 206940.24 | ... O6: =SUMIFS(O$11:O973,$B$11:$B973,"Actual") -> 1828114.5
B7: Budget Deficit/ Savings | C7: =C5-C6 -> -13385.48 | D7: =D5-D6 -> 12295.54 | E7: =E5-E6 -> 1524.88 | F7: =F5-F6 -> -5801.35 | G7: =G5-G6 -> -462.14 | H7: =H5-H6 -> -4329.42 | I7: =I5-I6 -> -34314.57 | J7: =J5-J6 -> -32187.27 | ... O7: =O5-O6 -> 314296.21
B8: Year to Date Spend | C8: =SUM($C6:C6) -> 167533.56 | D8: =SUM($C6:D6) -> 344688.8 | E8: =SUM($C6:E6) -> 539330 | F8: =SUM($C6:F6) -> 728439.5 | G8: =SUM($C6:G6) -> 914523.16 | H8: =SUM($C6:H6) -> 1100990.4 | I8: =SUM($C6:I6) -> 1319342.6 | J8: =SUM($C6:J6) -> 1526282.8 | ... N8: =SUM($C6:N6) -> 1828114.5 | O8: =O6 -> 1828114.5
B9: YTD Excess From Budget | C9: =SUM($C5:C5)-C8 -> -13385.48 | D9: =SUM($C5:D5)-D8 -> -1089.94 | E9: =SUM($C5:E5)-E8 -> 434.94 | F9: =SUM($C5:F5)-F8 -> -5366.41 | G9: =SUM($C5:G5)-G8 -> -5828.55 | H9: =SUM($C5:H5)-H8 -> -10157.97 | I9: =SUM($C5:I5)-I8 -> -44472.54 | J9: =SUM($C5:J5)-J8 -> -76659.81 | ... N9: =SUM($C5:N5)-N8 -> 314296.21
A11: World Media (TripAdvisor) | B11: Actual 2024 | C11: 4080.11 | D11: 4080.02 | E11: 5055.54 | O11: =SUM(C11:N11) -> 13215.67
B12: Estimated | P12: ?
B13: Budget | O13: =SUM(C13:N13) -> 0
B14: Actual | O14: =SUM(C14:N14) -> 0
A15: World Media (Display Video, Desk, & Simplifi) | B15: Actual 2024 | C15: 23728.84 | D15: 25101.35 | E15: 35455.78 | F15: 30823.51 | G15: 34320.48 | H15: 31083.3 | I15: 46651.12 | J15: 28881.14 | K15: 33040.97 | L15: 54634.92 | M15: 36526.24 | N15: 28723.21 | O15: =SUM(C15:N15) -> 408970.86
B16: Estimated | C16: 27915 | D16: 28740 | E16: 27740 | F16: 23500 | G16: 24000 | H16: 25046 | I16: 30153 | J16: 28740 | K16: 25240 | L16: 22000 | M16: 22000 | N16: 22000 | O16: =SUM(C16:N16) -> 307074
B17: Budget | O17: =SUM(C17:N17) -> 0
A18: Unlimited | B18: Actual | C18: 27010.09 | D18: 27771.94 | E18: 28635.33 | F18: =2627.29 + 13696.76 + 7123.68 -> 23447.73 | G18: =2937.5+13690.24+6974.2 -> 23601.94 | H18: =2519.17+15403.05+6547.48 -> 24469.7 | I18: =3830.28+13331.62+8573.84+1071.27 -> 26807.01 | J18: =6222.03+11760.15+6615.33+809.32 -> 25406.83 | K18: =4121.56+11093.88+9458.1+928.52 -> 25602.06 | L18: =4876.1+12331.45+6345.73+669.01 -> 24222.29 | O18: =SUM(C18:N18) -> 256974.92 | T18: =2627.29 +13696.76 +7123.68+ 2835 -> 26282.73
A19: World Media (Google/ SEM management fees) | B19: Actual 2024 | C19: 10396.22 | D19: 11973.43 | E19: 14258.09 | F19: 14596.9 | G19: 15566.91 | H19: 13568.25 | I19: 12885.75 | J19: 12381.23 | K19: 12090.85 | L19: 12045.27 | M19: 15738.74 | N19: 11505.59 | O19: =SUM(C19:N19) -> 157007.23
B20: Estimated | C20: 12007 | D20: 12907 | E20: 13772 | F20: 13325 | G20: 14099 | H20: 13342 | I20: 12557 | J20: 11437 | K20: 11761 | L20: 11652 | M20: 11980 | N20: 12090 | O20: =SUM(C20:N20) -> 150929
B21: Budget | O21: =SUM(C21:N21) -> 0
A22: Unlimited | B22: Actual | C22: 11759.1 | D22: 13371.99 | E22: 15324.07 | F22: =T22 -> 15750.9 | G22: =13835.66+1224.81 -> 15060.47 | H22: =13417.09+1208.88 -> 14625.97 | I22: =15940.09+1125.06 -> 17065.15 | J22: =15366.99+1204.03 -> 16571.02 | K22: =11569.11+1141.6 -> 12710.71 | L22: =12701.72+1167.32 -> 13869.04 | O22: =SUM(C22:N22) -> 146108.42 | T22: =14574.28 + 1176.62 -> 15750.9
A23: World Media (Ad Serving, Pass Along Cost) | B23: Actual 2024 | C23: 1865.66 | D23: 2071.98 | E23: 2523.65 | F23: 2662.37 | G23: 2758.1 | H23: 2512.19 | I23: 2333.57 | J23: 2308.11 | K23: 2492.39 | L23: 2761.25 | M23: 3312.05 | N23: 2514.09 | O23: =SUM(C23:N23) -> 30115.41
B24: Estimated | C24: 2430 | D24: 2574 | E24: 2659 | F24: 2237 | G24: 2350 | H24: 2270 | I24: 2570 | J24: 2379 | K24: 2317 | L24: 1985 | M24: 2029 | N24: 2044 | O24: =SUM(C24:N24) -> 27844
B25: Budget | O25: =SUM(C25:N25) -> 0
A26: Unlimited | B26: Actual | C26: 2348.92 | D26: 2651.88 | E26: 2901.93 | F26: 2835 | G26: 2803.67 | H26: 2526.42 | I26: 3245.04 | J26: 3259.19 | K26: 2626.51 | L26: =2537.33 -> 2537.33 | O26: =SUM(C26:N26) -> 27735.89
A27: World Media (SEM cc charges/Invoice)- Google | B27: Actual 2024 | C27: 61359.1 | D27: 71763.22 | E27: 87944.72 | F27: 89500.71 | G27: 98132.59 | H27: 76532.94 | I27: 87212.46 | J27: 82205.62 | K27: 79558.58 | L27: 79278.32 | M27: 101106.21 | N27: 70462.07 | O27: =SUM(C27:N27) -> 985056.54
B28: Estimated | C28: 80048 | D28: 86045 | E28: 91815 | F28: 88831 | G28: 93990 | H28: 88944 | I28: 83716 | J28: 76244 | K28: 78408 | L28: 77678 | M28: 79870 | N28: 80601 | O28: =SUM(C28:N28) -> 1006190
B29: Budget | O29: =SUM(C29:N29) -> 0
A30: Unlimited | B30: Actual | C30: 73580.71 | D30: 86812.28 | E30: 94038.6 | F30: 95076.47 | G30: 96180.01 | H30: 93644.6 | I30: =111299.05 -> 111299.05 | J30: 106684.02 | K30: 62362.41 | L30: 88507.3 | O30: =SUM(C30:N30) -> 908185.45
A31: Microsoft Advertising | B31: Actual 2024 | C31: 10449.98 | D31: 7348.92 | E31: 13648.39 | F31: 8388.62 | G31: 7406.11 | H31: 6347.45 | I31: 7395.7 | J31: 6291.66 | K31: 5242.36 | L31: 5243.94 | M31: 8390.36 | N31: 10486.3 | O31: =SUM(C31:N31) -> 96639.79
B32: Estimated | C32: 0 | D32: 0 | E32: 0 | F32: 0 | G32: 0 | H32: 0 | I32: 0 | J32: 0 | K32: 0 | L32: 0 | M32: 0 | N32: 0 | O32: =SUM(C32:N32) -> 0
B33: Budget | O33: =SUM(C33:N33) -> 0
B34: Actual | C34: 8401.23 | D34: 6314.85 | E34: 10948.41 | F34: 7616.42 | G34: =1049.98+1049.93+1050.82+1049.35+1047.16+1049.47+1048.68+1047.32 -> 8392.71 | H34: =1048.21+1051.36+1048.35+1049.65+1054.36+1050.66+1047.2+1048.41 -> 8398.2 | I34: 8671.2 | J34: 7345.99 | K34: 7352.35 | L34: 7870.58 | O34: =SUM(C34:N34) -> 81311.94
A35: Referral Rock (Commissions) | B35: Actual 2024 | O35: =SUM(C35:N35) -> 0
B36: Estimated | C36: 600 | D36: 600 | E36: 600 | F36: 600 | G36: 600 | H36: 600 | I36: 600 | J36: 600 | K36: 600 | L36: 600 | M36: =IF(ISBLANK(M38),M37,M38) -> 0 | N36: =IF(ISBLANK(N38),N37,N38) -> 0 | O36: =SUM(C36:N36) -> 6000
B37: Budget | O37: =SUM(C37:N37) -> 0
B38: Actual | O38: =SUM(C38:N38) -> 0
A39: Impact (Commisions) | B39: Actual 2024 | C39: 29593.72 | D39: 22425.13 | E39: 23018.05 | F39: 19396.51 | G39: 15622.07 | H39: 16940.29 | I39: 19042.02 | J39: 20211.42 | K39: 24772.37 | L39: 21996.24 | M39: 18628.08 | N39: 15919.31 | O39: =SUM(C39:N39) -> 247565.21
B40: Estimated | C40: $34, 032.78 | D40: 25788.9 | E40: 26470.76 | F40: 22305.99 | G40: 17965.38 | H40: 19481.33 | I40: 21898.32 | J40: 23243.13 | K40: 28488.23 | L40: 25295.68 | M40: 23000 | N40: 23000 | O40: =SUM(C40:N40) -> 256937.72
B41: Budget | O41: =SUM(C41:N41) -> 0
...

Sheet 5101-510 Non performance based
A1: 5101-510 Non performance based
C2: January | D2: February | E2: March | F2: April | G2: May | H2: June | I2: July | J2: August | K2: September | L2: October | M2: November | N2: December | O2: Total
A3: TOTAL | B3: Actual 2024 | C3: =SUMIFS(C$11:C960,$B$11:$B960,"Actual 2024") -> 54961.34 | D3: =SUMIFS(D$11:D960,$B$11:$B960,"Actual 2024") -> 52303.61 | E3: =SUMIFS(E$11:E960,$B$11:$B960,"Actual 2024") -> 53970.61 | F3: =SUMIFS(F$11:F960,$B$11:$B960,"Actual 2024") -> 62526.2 | G3: =SUMIFS(G$11:G960,$B$11:$B960,"Actual 2024") -> 50448.93 | H3: =SUMIFS(H$11:H960,$B$11:$B960,"Actual 2024") -> 33734.71 | I3: =SUMIFS(I$11:I960,$B$11:$B960,"Actual 2024") -> 36157.39 | J3: =SUMIFS(J$11:J960,$B$11:$B960,"Actual 2024") -> 43318.85 | ... O3: =SUMIFS(O$11:O960,$B$11:$B960,"Actual 2024") -> 579457.29
B4: Estimated | C4: =SUMIFS(C$11:C960,$B$11:$B960,"Estimated") -> 73939 | D4: =SUMIFS(D$11:D960,$B$11:$B960,"Estimated") -> 58654 | E4: =SUMIFS(E$11:E960,$B$11:$B960,"Estimated") -> 50860 | F4: =SUMIFS(F$11:F960,$B$11:$B960,"Estimated") -> 64316 | G4: =SUMIFS(G$11:G960,$B$11:$B960,"Estimated") -> 47360 | H4: =SUMIFS(H$11:H960,$B$11:$B960,"Estimated") -> 42133 | I4: =SUMIFS(I$11:I960,$B$11:$B960,"Estimated") -> 29860 | J4: =SUMIFS(J$11:J960,$B$11:$B960,"Estimated") -> 43399 | ... O4: =SUMIFS(O$11:O960,$B$11:$B960,"Estimated") -> 605565 | Q4: =O4-O3 -> 26107.71
B5: Budget | C5: 75939 | D5: 58654 | E5: 50860 | F5: 66316 | G5: 47360 | H5: 42133 | I5: 31860 | J5: 43399 | K5: 55360 | L5: 47149 | M5: 35760 | N5: 58775 | O5: =SUM(C5:N5) -> 613565 | P5: 613565
B6: Actual | C6: =SUMIFS(C$11:C969,$B$11:$B969,"Actual") -> 48578.52 | D6: =SUMIFS(D$11:D969,$B$11:$B969,"Actual") -> 47324.93 | E6: =SUMIFS(E$11:E969,$B$11:$B969,"Actual") -> 43482.71 | F6: =SUMIFS(F$11:F969,$B$11:$B969,"Actual") -> 73020.92 | G6: =SUMIFS(G$11:G969,$B$11:$B969,"Actual") -> 35157.55 | H6: =SUMIFS(H$11:H969,$B$11:$B969,"Actual") -> 57157.04 | I6: =SUMIFS(I$11:I969,$B$11:$B969,"Actual") -> 37818.82 | J6: =SUMIFS(J$11:J969,$B$11:$B969,"Actual") -> 50222.33 | ... O6: =SUMIFS(O$11:O969,$B$11:$B969,"Actual") -> 491972.19 | Q6: =O6-P6 -> 491972.19
B7: Budget Deficit/ Savings | C7: =C5-C6 -> 27360.48 | D7: =D5-D6 -> 11329.07 | E7: =E5-E6 -> 7377.29 | F7: =F5-F6 -> -6704.92 | G7: =G5-G6 -> 12202.45 | H7: =H5-H6 -> -15024.04 | I7: =I5-I6 -> -5958.82 | J7: =J5-J6 -> -6823.33 | ... O7: =O5-O6 -> 121592.81
B8: Year to Date Spend | C8: =SUM($C6:C6) -> 48578.52 | D8: =SUM($C6:D6) -> 95903.45 | E8: =SUM($C6:E6) -> 139386.16 | F8: =SUM($C6:F6) -> 212407.08 | G8: =SUM($C6:G6) -> 247564.63 | H8: =SUM($C6:H6) -> 304721.67 | I8: =SUM($C6:I6) -> 342540.49 | J8: =SUM($C6:J6) -> 392762.82 | ... N8: =SUM($C6:N6) -> 491972.19 | O8: =O6 -> 491972.19
B9: YTD Excess From Budget | C9: =SUM($C5:C5)-C8 -> 27360.48 | D9: =SUM($C5:D5)-D8 -> 38689.55 | E9: =SUM($C5:E5)-E8 -> 46066.84 | F9: =SUM($C5:F5)-F8 -> 39361.92 | G9: =SUM($C5:G5)-G8 -> 51564.37 | H9: =SUM($C5:H5)-H8 -> 36540.33 | I9: =SUM($C5:I5)-I8 -> 30581.51 | J9: =SUM($C5:J5)-J8 -> 23758.18 | ... N9: =SUM($C5:N5)-N8 -> 121592.81
A11: Element 8 West Bound market | B11: Actual 2024 | C11: 44302 | D11: 32940 | E11: 27857 | F11: 33380 | G11: 27856.53 | H11: 33380 | I11: 27857 | J11: 33380 | K11: 27857 | L11: 33380.09 | M11: 27856.53 | N11: 56044.4 | O11: =SUM(C11:N11) -> 406090.55
B12: Estimated | C12: 45639 | D12: 41293 | E12: 29260 | F12: 34783 | G12: 29260 | H12: 34783 | I12: 29260 | J12: 34783 | K12: 29260 | L12: 34783 | M12: 29260 | N12: 46509 | O12: =SUM(C12:N12) -> 418873
B13: Budget | O13: =SUM(C13:N13) -> 0
B14: Actual | C14: 39146.58 | D14: 29277.48 | E14: 28753.92 | F14: 46267 | G14: 29259.67 | H14: 34783.23 | I14: =29259.67 -> 29259.67 | J14: 34783.23 | K14: 37147.63 | L14: 37173.81 | O14: =SUM(C14:N14) -> 345852.22
A15: Element 8 Local market | B15: Actual 2024 | C15: 10383.24 | D15: 19113.61 | E15: 19113.61 | F15: 25942.2 | G15: 22342.4 | H15: 104.71 | I15: 104.71 | J15: 9688.85 | K15: 18291.26 | L15: 5549.74 | M15: 4149.74 | N15: 6364.92 | O15: =SUM(C15:N15) -> 141148.99
B16: Estimated | C16: 11000 | D16: 16000 | E16: 15000 | F16: 25000 | G16: 15000 | H16: 0 | I16: 0 | J16: 8016 | K16: 22000 | L16: 6766 | M16: 5900 | N16: 11666 | O16: =SUM(C16:N16) -> 136348
B17: Budget | O17: =SUM(C17:N17) -> 0
B18: Actual | C18: 837.7 | D18: 16037.69 | E18: 8184.29 | F18: =73020.92-46267 -> 26753.92 | G18: 5897.88 | H18: 19283.75 | I18: =8559.15 -> 8559.15 | J18: 0 | K18: 8647.12 | L18: 9847.1 | O18: =SUM(C18:N18) -> 104048.6
A19: Hemisphere (United Airlines) inflight magazine (INK) | B19: Actual 2024 | E19: 6750 | O19: =SUM(C19:N19) -> 6750
B20: Estimated | C20: 0 | D20: 0 | E20: 0 | F20: 0 | G20: 0 | H20: 6750 | I20: 0 | J20: 0 | K20: 0 | L20: 0 | M20: 0 | N20: 0 | O20: =SUM(C20:N20) -> 6750
B21: Budget | O21: =SUM(C21:N21) -> 0
B22: Actual | O22: =SUM(C22:N22) -> 0
A23: Activities and Attraction Association of Hawaii | B23: Actual 2024 | O23: =SUM(C23:N23) -> 0
B24: Estimated | C24: 0 | D24: 0 | E24: 0 | F24: 0 | G24: 0 | H24: 0 | I24: 0 | J24: 0 | K24: 0 | L24: 0 | M24: 0 | N24: 0 | O24: =SUM(C24:N24) -> 0
B25: Budget | O25: =SUM(C25:N25) -> 0
B26: Actual | O26: =SUM(C26:N26) -> 0
A27: North Shore Map | B27: Actual 2024 | O27: =SUM(C27:N27) -> 0
B28: Estimated | C28: 0 | D28: 0 | E28: 0 | F28: 0 | G28: 0 | H28: 0 | I28: 0 | J28: 0 | K28: 0 | L28: 0 | M28: 0 | N28: 0 | O28: =SUM(C28:N28) -> 0
B29: Budget | O29: =SUM(C29:N29) -> 0
B30: Actual | O30: =SUM(C30:N30) -> 0
A31: Photoshoot (Hawaii Store) | B31: Actual 2024 | C31: 17.35 | O31: =SUM(C31:N31) -> 17.35
B32: Estimated | C32: =IF(ISBLANK(C34),C33,C34) -> 0 | D32: =IF(ISBLANK(D34),D33,D34) -> 0 | E32: =IF(ISBLANK(E34),E33,E34) -> 0 | F32: =IF(ISBLANK(F34),F33,F34) -> 0 | G32: =IF(ISBLANK(G34),G33,G34) -> 0 | H32: =IF(ISBLANK(H34),H33,H34) -> 0 | I32: =IF(ISBLANK(I34),I33,I34) -> 0 | J32: =IF(ISBLANK(J34),J33,J34) -> 0 | ... N32: =IF(ISBLANK(N34),N33,N34) -> 0 | O32: =SUM(C32:N32) -> 0
B33: Budget | O33: =SUM(C33:N33) -> 0
B34: Actual | O34: =SUM(C34:N34) -> 0
A35: Tango Card | B35: Actual 2024 | C35: 258.75 | D35: 250 | E35: 250 | F35: 250 | G35: 250 | H35: 250 | I35: 250 | J35: 250 | K35: 250 | L35: 250 | M35: 250 | N35: 250 | O35: =SUM(C35:N35) -> 3008.75
B36: Estimated | C36: =IF(ISBLANK(C38),C37,C38) -> 0 | D36: =IF(ISBLANK(D38),D37,D38) -> 0 | E36: =IF(ISBLANK(E38),E37,E38) -> 0 | F36: =IF(ISBLANK(F38),F37,F38) -> 0 | G36: =IF(ISBLANK(G38),G37,G38) -> 0 | H36: =IF(ISBLANK(H38),H37,H38) -> 0 | I36: =IF(ISBLANK(I38),I37,I38) -> 0 | J36: =IF(ISBLANK(J38),J37,J38) -> 0 | ... N36: =IF(ISBLANK(N38),N37,N38) -> 0 | O36: =SUM(C36:N36) -> 0
B37: Budget | O37: =SUM(C37:N37) -> 0
B38: Actual | O38: =SUM(C38:N38) -> 0
A39: dotComm Awards | B39: Actual 2024 | I39: 375 | O39: =SUM(C39:N39) -> 375
B40: Estimated | C40: 0 | D40: 0 | E40: 0 | F40: 0 | G40: 0 | H40: 0 | I40: 0 | J40: 0 | K40: 0 | L40: 0 | M40: 0 | N40: 0 | O40: =SUM(C40:N40) -> 0
B41: Budget | O41: =SUM(C41:N41) -> 0
...

Sheet 5102-510 Advertising Agency Fee
A1: 5102-510 Advertising Agency Fees
C2: January | D2: February | E2: March | F2: April | G2: May | H2: June | I2: July | J2: August | K2: September | L2: October | M2: November | N2: December | O2: Total
A3: TOTAL | B3: Actual 2024 | C3: =SUMIFS(C$11:C991,$B$11:$B991,"Actual 2024") -> 30663.22 | D3: =SUMIFS(D$11:D991,$B$11:$B991,"Actual 2024") -> 34061.61 | E3: =SUMIFS(E$11:E991,$B$11:$B991,"Actual 2024") -> 48123.82 | F3: =SUMIFS(F$11:F991,$B$11:$B991,"Actual 2024") -> 35442.91 | G3: =SUMIFS(G$11:G991,$B$11:$B991,"Actual 2024") -> 57806.73 | H3: =SUMIFS(H$11:H991,$B$11:$B991,"Actual 2024") -> 42091.03 | I3: =SUMIFS(I$11:I991,$B$11:$B991,"Actual 2024") -> 39212.95 | J3: =SUMIFS(J$11:J991,$B$11:$B991,"Actual 2024") -> 38385.77 | ... O3: =SUMIFS(O$11:O991,$B$11:$B991,"Actual 2024") -> 489117.25
B4: Estimated | C4: =SUMIFS(C$11:C991,$B$11:$B991,"Estimated") -> 67567 | D4: =SUMIFS(D$11:D991,$B$11:$B991,"Estimated") -> 97522 | E4: =SUMIFS(E$11:E991,$B$11:$B991,"Estimated") -> 58826 | F4: =SUMIFS(F$11:F991,$B$11:$B991,"Estimated") -> 51522 | G4: =SUMIFS(G$11:G991,$B$11:$B991,"Estimated") -> 65022 | H4: =SUMIFS(H$11:H991,$B$11:$B991,"Estimated") -> 49022 | I4: =SUMIFS(I$11:I991,$B$11:$B991,"Estimated") -> 47085 | J4: =SUMIFS(J$11:J991,$B$11:$B991,"Estimated") -> 47022 | ... O4: =SUMIFS(O$11:O991,$B$11:$B991,"Estimated") -> 697176 | Q4: =O4-O3 -> 208058.75
B5: Budget | C5: 67567 | D5: 97522 | E5: 58826 | F5: 51522 | G5: 65022 | H5: 49022 | I5: 47085 | J5: 47022 | K5: 47522 | L5: 56022 | M5: 57522 | N5: 52522 | O5: =SUM(C5:N5) -> 697176 | P5: 697176
B6: Actual | C6: =SUMIFS(C$11:C996,$B$11:$B996,"Actual") -> 51418.5 | D6: =SUMIFS(D$11:D996,$B$11:$B996,"Actual") -> 59616.7 | E6: =SUMIFS(E$11:E996,$B$11:$B996,"Actual") -> 47803.15 | F6: =SUMIFS(F$11:F996,$B$11:$B996,"Actual") -> 54958.58 | G6: =SUMIFS(G$11:G996,$B$11:$B996,"Actual") -> 55320.83 | H6: =SUMIFS(H$11:H996,$B$11:$B996,"Actual") -> 58388.51 | I6: =SUMIFS(I$11:I996,$B$11:$B996,"Actual") -> 63125.88 | J6: =SUMIFS(J$11:J996,$B$11:$B996,"Actual") -> 59393.07 | ... O6: =SUMIFS(O$11:O996,$B$11:$B996,"Actual") -> 528819.66
B7: Budget Deficit/ Savings | C7: =C5-C6 -> 16148.5 | D7: =D5-D6 -> 37905.3 | E7: =E5-E6 -> 11022.85 | F7: =F5-F6 -> -3436.58 | G7: =G5-G6 -> 9701.17 | H7: =H5-H6 -> -9366.51 | I7: =I5-I6 -> -16040.88 | J7: =J5-J6 -> -12371.07 | ... O7: =O5-O6 -> 168356.34
B8: Year to Date Spend | C8: =SUM($C6:C6) -> 51418.5 | D8: =SUM($C6:D6) -> 111035.2 | E8: =SUM($C6:E6) -> 158838.35 | F8: =SUM($C6:F6) -> 213796.93 | G8: =SUM($C6:G6) -> 269117.76 | H8: =SUM($C6:H6) -> 327506.27 | I8: =SUM($C6:I6) -> 390632.15 | J8: =SUM($C6:J6) -> 450025.22 | ... N8: =SUM($C6:N6) -> 528819.66 | O8: =O6 -> 528819.66
B9: YTD Excess From Budget | C9: =SUM($C5:C5)-C8 -> 16148.5 | D9: =SUM($C5:D5)-D8 -> 54053.8 | E9: =SUM($C5:E5)-E8 -> 65076.65 | F9: =SUM($C5:F5)-F8 -> 61640.07 | G9: =SUM($C5:G5)-G8 -> 71341.24 | H9: =SUM($C5:H5)-H8 -> 61974.73 | I9: =SUM($C5:I5)-I8 -> 45933.85 | J9: =SUM($C5:J5)-J8 -> 33562.78 | ... N9: =SUM($C5:N5)-N8 -> 168356.34
A11: World Media (Analytics Retainer & Agency Fee) | B11: Actual 2024 | C11: 8000 | D11: 8000 | E11: 8000 | F11: 8000 | G11: 8000 | H11: 8000 | I11: 8000 | J11: 8000 | K11: 8000 | L11: 8000 | M11: 8000 | N11: 8000 | O11: =SUM(C11:N11) -> 96000
B12: Estimated | C12: 8000 | D12: 10500 | E12: 10500 | F12: 10500 | G12: 10500 | H12: 10500 | I12: 10500 | J12: 10500 | K12: 10500 | L12: 10500 | M12: 10500 | N12: 10500 | O12: =SUM(C12:N12) -> 123500 | U12: Harley Charlebois | X12: Jairus Roda
B13: Budget | O13: =SUM(C13:N13) -> 0 | U13: Ephraim Tacuban | X13: Jonah Bawden
B14: Actual | C14: 8000 | D14: 10500 | E14: 10500 | F14: 10500 | G14: 10500 | H14: 10500 | I14: 10500 | J14: =10500+1650 -> 12150 | O14: =SUM(C14:N14) -> 83150 | U14: Shazer Llanera | X14: Nicholas Johnson
A15: World Media (SEO Retainer) | B15: Actual 2024 | U15: Nani Laie (Mike Foley) | X15: David Newbold
B16: Estimated | C16: 5000 | D16: 5000 | E16: 5000 | F16: 5000 | G16: 5000 | H16: 5000 | I16: 5000 | J16: 5000 | K16: 5000 | L16: 5000 | M16: 5000 | N16: 5000 | O16: =SUM(C16:N16) -> 60000 | U16: Sam Merrill | X16: Geo Growth
B17: Budget | U17: Conor Lunt | X17: AI Revolution Labs
B18: Actual | D18: 5000 | E18: 5000 | F18: 5000 | G18: 5000 | H18: 5000 | I18: 5000 | J18: 5000 | O18: =SUM(C18:N18) -> 35000 | U18: Tanner Fernandez | X18: Ric Noyle
A19: World Media Interactive: Run Analytics setup fee | B19: Actual 2024 | O19: =SUM(C19:N19) -> 0 | U19: Marc Purles | X19: Telesia Tonga
B20: Estimated | C20: 0 | D20: 50000 | E20: 0 | F20: 0 | G20: 0 | H20: 0 | I20: 0 | J20: 0 | K20: 0 | L20: 0 | M20: 0 | N20: 0 | O20: =SUM(C20:N20) -> 50000 | U20: Karizza Llanera | X20: Kasey Padgett
B21: Budget | O21: =SUM(C21:N21) -> 0 | U21: Photography/Videography contractor (Isaac) | X21: Evette Loo
B22: Actual | O22: =SUM(C22:N22) -> 0 | U22: David Butterfield | X22: Manuarii Tefan
A23: Pacific Digital Signs | B23: Actual 2024 | E23: 1303.66 | O23: =SUM(C23:N23) -> 1303.66 | U23: Hisaka Inumaki | X23: Bright Edge - Enterprise SEO Platform: Heavy Overlap with Ahrefs
B24: Estimated | C24: 0 | D24: 0 | E24: 1304 | F24: 0 | G24: 0 | H24: 0 | I24: 0 | J24: 0 | K24: 0 | L24: 0 | M24: 0 | N24: 0 | O24: =SUM(C24:N24) -> 1304 | U24: Harold Pedroso
B25: Budget | O25: =SUM(C25:N25) -> 0 | U25: Bala Pilli
B26: Actual | O26: =SUM(C26:N26) -> 0 | U26: Khoon An
A27: Sound Partner (Jeremy) | B27: Actual 2024 | C27: 2000 | D27: 2000 | E27: 2000 | F27: 2000 | G27: 2000 | H27: 2000 | I27: 2000 | J27: 2000 | K27: 2000 | L27: 2000 | M27: 2000 | N27: 2000 | O27: =SUM(C27:N27) -> 24000 | U27: Kyle Vreeken
B28: Estimated | C28: 2000 | D28: 2000 | E28: 2000 | F28: 2000 | G28: 2000 | H28: 2000 | I28: 2000 | J28: 2000 | K28: 2000 | L28: 2000 | M28: 2000 | N28: 2000 | O28: =SUM(C28:N28) -> 24000 | U28: Antoinette Yee
A29: Affiliate Program Manager in Impact | B29: Budget | O29: =SUM(C29:N29) -> 0 | U29: A Hardflip Production LLC
B30: Actual | C30: 2000 | D30: 2000 | E30: 2000 | F30: 2000 | G30: 2000 | H30: 2000 | I30: 2000 | J30: 2000 | K30: 2000 | L30: 2000 | O30: =SUM(C30:N30) -> 20000 | U30: Tetrachrome (Joseph Trisolini)
A31: Element 8 (Retainers) | B31: Actual 2024 | C31: 7283.77 | D31: 7283.77 | E31: 7283.77 | F31: 7283.77 | G31: 7283.77 | H31: 7283.77 | I31: 7283.77 | J31: 7283.77 | K31: 7283.77 | L31: 7283.77 | M31: 7283.77 | N31: 7283.77 | O31: =SUM(C31:N31) -> 87405.24 | U31: Nick Gruen
B32: Estimated | C32: 8625 | D32: 8625 | E32: 8625 | F32: 8625 | G32: 8625 | H32: 8625 | I32: 8625 | J32: 8625 | K32: 8625 | L32: 8625 | M32: 8625 | N32: 8625 | O32: =SUM(C32:N32) -> 103500
B33: Budget | O33: =SUM(C33:N33) -> 0
B34: Actual | C34: 9031.41 | D34: 9031.41 | E34: 9031.41 | F34: 9031.41 | G34: 9031.41 | H34: 9031.41 | I34: =9031.41 -> 9031.41 | J34: =9031.41 -> 9031.41 | K34: =9031.41 -> 9031.41 | L34: 9031.41 | O34: =SUM(C34:N34) -> 90314.1
A35: Element 8 (Creative services) | B35: Actual 2024 | C35: 4462.82 | D35: 4211.46 | E35: 13958.01 | F35: 4450.26 | G35: 26013.08 | H35: 10241.88 | I35: 5919.36 | J35: 9637.12 | K35: 8813.45 | L35: 13923.55 | M35: 13156.34 | N35: 15187.12 | O35: =SUM(C35:N35) -> 129974.45
B36: Estimated | C36: 5000 | D36: 5000 | E36: 15000 | F36: 5000 | G36: 27000 | H36: 11000 | I36: 6000 | J36: 11000 | K36: 10000 | L36: 15000 | M36: 14000 | N36: 14000 | O36: =SUM(C36:N36) -> 138000
B37: Budget | O37: =SUM(C37:N37) -> 0
B38: Actual | C38: 19336.71 | D38: 14493.1 | E38: 4581.15 | F38: 12237.69 | G38: 10465.44 | H38: 14566.22 | I38: =16659.15 -> 16659.15 | J38: 11471.28 | K38: 24445.58 | L38: 7436.28 | O38: =SUM(C38:N38) -> 135692.6
A39: The Design Farm | B39: Actual 2024 | O39: =SUM(C39:N39) -> 0
B40: Estimated | C40: 0 | D40: 0 | E40: 0 | F40: 0 | G40: 0 | H40: 0 | I40: 0 | J40: 0 | K40: 0 | L40: 0 | M40: 0 | N40: 0 | O40: =SUM(C40:N40) -> 0
B41: Budget | O41: =SUM(C41:N41) -> 0
...

Sheet 5104-510 Public Relations
A1: 5104-510 Public Relations
C2: January | D2: February | E2: March | F2: April | G2: May | H2: June | I2: July | J2: August | K2: September | L2: October | M2: November | N2: December | O2: Total
A3: TOTAL | B3: Actual 2024 | C3: =SUMIFS(C$11:C996,$B$11:$B996,"Actual 2024") -> 8376.96 | D3: =SUMIFS(D$11:D996,$B$11:$B996,"Actual 2024") -> 8376.96 | E3: =SUMIFS(E$11:E996,$B$11:$B996,"Actual 2024") -> 8376.96 | F3: =SUMIFS(F$11:F996,$B$11:$B996,"Actual 2024") -> 17177.88 | G3: =SUMIFS(G$11:G996,$B$11:$B996,"Actual 2024") -> 23701.57 | H3: =SUMIFS(H$11:H996,$B$11:$B996,"Actual 2024") -> 11057.63 | I3: =SUMIFS(I$11:I996,$B$11:$B996,"Actual 2024") -> 10209.42 | J3: =SUMIFS(J$11:J996,$B$11:$B996,"Actual 2024") -> 10209.42 | ... O3: =SUMIFS(O$11:O996,$B$11:$B996,"Actual 2024") -> 157545.37
B4: Estimated | C4: =SUMIFS(C$11:C996,$B$11:$B996,"Estimated") -> 10209.46 | D4: =SUMIFS(D$11:D996,$B$11:$B996,"Estimated") -> 10209.46 | E4: =SUMIFS(E$11:E996,$B$11:$B996,"Estimated") -> 21832.46 | F4: =SUMIFS(F$11:F996,$B$11:$B996,"Estimated") -> 10209.46 | G4: =SUMIFS(G$11:G996,$B$11:$B996,"Estimated") -> 16832.46 | H4: =SUMIFS(H$11:H996,$B$11:$B996,"Estimated") -> 10209.46 | I4: =SUMIFS(I$11:I996,$B$11:$B996,"Estimated") -> 10209.46 | J4: =SUMIFS(J$11:J996,$B$11:$B996,"Estimated") -> 10209.46 | ... O4: =SUMIFS(O$11:O996,$B$11:$B996,"Estimated") -> 152382.52 | Q4: =O4-O3 -> -5162.85
B5: Budget | C5: 10209.46 | D5: 10209.46 | E5: 21832.46 | F5: 10209.46 | G5: 16832.46 | H5: 10209.46 | I5: 10209.46 | J5: 10209.46 | K5: 21832.46 | L5: 10209.46 | M5: 10209.46 | N5: 10209.46 | O5: =SUM(C5:N5) -> 152382.52 | P5: 152382.52
B6: Actual | C6: =SUMIFS(C$11:C1001,$B$11:$B1001,"Actual") -> 10467.72 | D6: =SUMIFS(D$11:D1001,$B$11:$B1001,"Actual") -> 12294.22 | E6: =SUMIFS(E$11:E1001,$B$11:$B1001,"Actual") -> 10209.42 | F6: =SUMIFS(F$11:F1001,$B$11:$B1001,"Actual") -> 9126.96 | G6: =SUMIFS(G$11:G1001,$B$11:$B1001,"Actual") -> 21267.29 | H6: =SUMIFS(H$11:H1001,$B$11:$B1001,"Actual") -> 13282.01 | I6: =SUMIFS(I$11:I1001,$B$11:$B1001,"Actual") -> 8376.96 | J6: =SUMIFS(J$11:J1001,$B$11:$B1001,"Actual") -> 8376.96 | ... O6: =SUMIFS(O$11:O1001,$B$11:$B1001,"Actual") -> 103610.96
B7: Budget Deficit/ Savings | C7: =C5-C6 -> -258.26 | D7: =D5-D6 -> -2084.76 | E7: =E5-E6 -> 11623.04 | F7: =F5-F6 -> 1082.5 | G7: =G5-G6 -> -4434.83 | H7: =H5-H6 -> -3072.55 | I7: =I5-I6 -> 1832.5 | J7: =J5-J6 -> 1832.5 | ... O7: =O5-O6 -> 48771.56 | P7: =O4-O7 -> 103610.96
B8: Year to Date Spend | C8: =SUM($C6:C6) -> 10467.72 | D8: =SUM($C6:D6) -> 22761.94 | E8: =SUM($C6:E6) -> 32971.36 | F8: =SUM($C6:F6) -> 42098.32 | G8: =SUM($C6:G6) -> 63365.61 | H8: =SUM($C6:H6) -> 76647.62 | I8: =SUM($C6:I6) -> 85024.58 | J8: =SUM($C6:J6) -> 93401.54 | ... N8: =SUM($C6:N6) -> 103610.96 | O8: =O6 -> 103610.96
B9: YTD Excess From Budget | C9: =SUM($C5:C5)-C8 -> -258.26 | D9: =SUM($C5:D5)-D8 -> -2343.02 | E9: =SUM($C5:E5)-E8 -> 9280.02 | F9: =SUM($C5:F5)-F8 -> 10362.52 | G9: =SUM($C5:G5)-G8 -> 5927.69 | H9: =SUM($C5:H5)-H8 -> 2855.14 | I9: =SUM($C5:I5)-I8 -> 4687.64 | J9: =SUM($C5:J5)-J8 -> 6520.14 | ... N9: =SUM($C5:N5)-N8 -> 48771.56
A11: Anthology- Finn Partners | B11: Actual 2024 | C11: 8376.96 | D11: 8376.96 | E11: 8376.96 | F11: 8376.96 | G11: 12273.07 | H11: 9225.17 | I11: 8376.96 | J11: 8376.96 | K11: 10763.79 | L11: 8376.96 | M11: 18848.16 | N11: 8376.96 | O11: =SUM(C11:N11) -> 118125.87
B12: Estimated | C12: 8377 | D12: 8377 | E12: 20000 | F12: 8377 | G12: 15000 | H12: 8377 | I12: 8377 | J12: 8377 | K12: 20000 | L12: 8377 | M12: 8377 | N12: 8377 | O12: =SUM(C12:N12) -> 130393
B13: Budget | O13: =SUM(C13:N13) -> 0
B14: Actual | C14: 8635.26 | D14: 8376.96 | E14: 8376.96 | F14: =8376.96+750 -> 9126.96 | G14: =8376.96+12709.92 -> 21086.88 | H14: =222.87+4682.18+8376.96 -> 13282.01 | I14: =8376.96 -> 8376.96 | J14: 8376.96 | K14: 8376.96 | O14: =SUM(C14:N14) -> 94015.91
A15: S. Morris and Associates, LLC | B15: Actual 2024 | F15: 1832.46 | G15: 1832.46 | H15: 1832.46 | I15: 1832.46 | J15: 1832.46 | K15: 1832.46 | L15: 1832.46 | M15: 1832.46 | N15: 1832.46 | O15: =SUM(C15:N15) -> 16492.14
B16: Estimated | C16: 1832.46 | D16: 1832.46 | E16: 1832.46 | F16: 1832.46 | G16: 1832.46 | H16: 1832.46 | I16: 1832.46 | J16: 1832.46 | K16: 1832.46 | L16: 1832.46 | M16: 1832.46 | N16: 1832.46 | O16: =SUM(C16:N16) -> 21989.52
B17: Budget | O17: =SUM(C17:N17) -> 0
B18: Actual | C18: 1832.46 | D18: 1832.46 | E18: 1832.46 | K18: 1832.46 | O18: =SUM(C18:N18) -> 7329.84
A19: Delta Airlines | B19: Actual 2024 | F19: 6968.46 | O19: =SUM(C19:N19) -> 6968.46
B20: Estimated | C20: 0 | D20: 0 | E20: 0 | F20: 0 | G20: 0 | H20: 0 | I20: 0 | J20: 0 | K20: 0 | L20: 0 | M20: 0 | N20: 0 | O20: =SUM(C20:N20) -> 0
B21: Budget | O21: =SUM(C21:N21) -> 0
B22: Actual | O22: =SUM(C22:N22) -> 0
A23: American Broadcasting Companies Inc. | B23: Actual 2024 | G23: 9596.04 | O23: =SUM(C23:N23) -> 9596.04
B24: Estimated | C24: 0 | D24: 0 | E24: 0 | F24: 0 | G24: 0 | H24: 0 | I24: 0 | J24: 0 | K24: 0 | L24: 0 | M24: 0 | N24: 0 | O24: =SUM(C24:N24) -> 0
B25: Budget | O25: =SUM(C25:N25) -> 0
B26: Actual | O26: =SUM(C26:N26) -> 0
A27: Southwest | B27: Actual 2024 | L27: 441.4 | O27: =SUM(C27:N27) -> 441.4
B28: Estimated | C28: 0 | D28: 0 | E28: 0 | F28: 0 | G28: 0 | H28: 0 | I28: 0 | J28: 0 | K28: 0 | L28: 0 | M28: 0 | N28: 0 | O28: =SUM(C28:N28) -> 0
B29: Budget | O29: =SUM(C29:N29) -> 0
B30: Actual | O30: =SUM(C30:N30) -> 0
A31: Air Canada | B31: Actual 2024 | L31: 789.36 | O31: =SUM(C31:N31) -> 789.36
B32: Estimated | C32: 0 | D32: 0 | E32: 0 | F32: 0 | G32: 0 | H32: 0 | I32: 0 | J32: 0 | K32: 0 | L32: 0 | M32: 0 | N32: 0 | O32: =SUM(C32:N32) -> 0
B33: Budget | O33: =SUM(C33:N33) -> 0
B34: Actual | O34: =SUM(C34:N34) -> 0
A35: United | B35: Actual 2024 | L35: 649.42 | O35: =SUM(C35:N35) -> 649.42
B36: Estimated | C36: 0 | D36: 0 | E36: 0 | F36: 0 | G36: 0 | H36: 0 | I36: 0 | J36: 0 | K36: 0 | L36: 0 | M36: 0 | N36: 0 | O36: =SUM(C36:N36) -> 0
B37: Budget | O37: =SUM(C37:N37) -> 0
B38: Actual | O38: =SUM(C38:N38) -> 0
A39: Hawaiian Airlines | B39: Actual 2024 | M39: 2971.22 | O39: =SUM(C39:N39) -> 2971.22
B40: Estimated | C40: 0 | D40: 0 | E40: 0 | F40: 0 | G40: 0 | H40: 0 | I40: 0 | J40: 0 | K40: 0 | L40: 0 | M40: 0 | N40: 0 | O40: =SUM(C40:N40) -> 0
B41: Budget | O41: =SUM(C41:N41) -> 0
...

Sheet 5105-510 Promotional Events
A1: 5105-510 Promotional Events
C2: January | D2: February | E2: March | F2: April | G2: May | H2: June | I2: July | J2: August | K2: September | L2: October | M2: November | N2: December | O2: Total
A3: TOTAL | B3: Actual 2024 | C3: =SUMIFS(C$11:C996,$B$11:$B996,"Actual 2024") -> 0 | D3: =SUMIFS(D$11:D996,$B$11:$B996,"Actual 2024") -> 0 | E3: =SUMIFS(E$11:E996,$B$11:$B996,"Actual 2024") -> 0 | F3: =SUMIFS(F$11:F996,$B$11:$B996,"Actual 2024") -> 0 | G3: =SUMIFS(G$11:G996,$B$11:$B996,"Actual 2024") -> 0 | H3: =SUMIFS(H$11:H996,$B$11:$B996,"Actual 2024") -> 0 | I3: =SUMIFS(I$11:I996,$B$11:$B996,"Actual 2024") -> 0 | J3: =SUMIFS(J$11:J996,$B$11:$B996,"Actual 2024") -> 0 | ... O3: =SUMIFS(O$11:O996,$B$11:$B996,"Actual 2024") -> 0
B4: Estimated | C4: =SUMIFS(C$11:C996,$B$11:$B996,"Estimated") -> 0 | D4: =SUMIFS(D$11:D996,$B$11:$B996,"Estimated") -> 0 | E4: =SUMIFS(E$11:E996,$B$11:$B996,"Estimated") -> 0 | F4: =SUMIFS(F$11:F996,$B$11:$B996,"Estimated") -> 0 | G4: =SUMIFS(G$11:G996,$B$11:$B996,"Estimated") -> 0 | H4: =SUMIFS(H$11:H996,$B$11:$B996,"Estimated") -> 0 | I4: =SUMIFS(I$11:I996,$B$11:$B996,"Estimated") -> 0 | J4: =SUMIFS(J$11:J996,$B$11:$B996,"Estimated") -> 0 | ... O4: =SUMIFS(O$11:O996,$B$11:$B996,"Estimated") -> 0 | Q4: =O4-O3 -> 0
B5: Budget | C5: 0 | D5: 0 | E5: 0 | F5: 0 | G5: 0 | H5: 0 | I5: 0 | J5: 0 | K5: 0 | L5: 0 | M5: 0 | N5: 0 | O5: =SUM(C5:N5) -> 0 | P5: 0
B6: Actual | C6: =SUMIFS(C$11:C1001,$B$11:$B1001,"Actual") -> 2008.82 | D6: =SUMIFS(D$11:D1001,$B$11:$B1001,"Actual") -> 2770.4 | E6: =SUMIFS(E$11:E1001,$B$11:$B1001,"Actual") -> 55.81 | F6: =SUMIFS(F$11:F1001,$B$11:$B1001,"Actual") -> 2373.42 | G6: =SUMIFS(G$11:G1001,$B$11:$B1001,"Actual") -> 1969.39 | H6: =SUMIFS(H$11:H1001,$B$11:$B1001,"Actual") -> 3896.16 | I6: =SUMIFS(I$11:I1001,$B$11:$B1001,"Actual") -> 96.71 | J6: =SUMIFS(J$11:J1001,$B$11:$B1001,"Actual") -> 7626.13 | ... O6: =SUMIFS(O$11:O1001,$B$11:$B1001,"Actual") -> 27328.19
